Workbook

Sheet PRODUCTOS
A1: ID | B1: CODIGO | C1: CATEGORIA | D1: SUBCATEGORIA | E1: MARCA | F1: PRODUCTO | G1: FRAGANCIA | H1: PRESENTACION | I1: NOMBRE FOTO | J1: COSTO | K1: % MARGEN | L1: PRECIO VENTA | M1: STOCK | N1: STOCK MINIMO | O1: ESTADO | P1: DESTACADO | Q1: SLUG | R1: DESCRIPCION | S1: CARACTERISTICAS | T1: EMPAQUE/PRODUCTO | U1: VIÁTICO PRORRATEADO | V1: SUBSIDIO ENVÍO PRORR. | W1: COMISIÓN COBRO | X1: MARGEN BRUTO OBJ. | Y1: PRECIO VENTA AJUSTADO | Z1: GANANCIA BRUTA EST. | AA1: MARGEN BRUTO EST. | AB1: GRUPO | AC1: VARIANTE
A2: 001 | B2: CLO001 | C2: 🚽 Baño | D2: Lavandina | E2: bethel | F2: Lavandina al 4% | G2: sin frangancia | H2: 5 litros | I2: CLO001.jpg | J2: 3300 | K2: 0.4 | L2: =IF(J2="","",J2*(1+K2)) -> 4620 | M2: Activo | O2: Activo | P2: NO | Q2: CLO001 | R2: Lavandina al 4%. Presentación: 5 litros. | S2: Lavandina. Elimina suciedad y gérmenes en inodoros, azulejos y superficies del baño, dejando un aroma agradable. | T2: ='SUPUESTOS PRECIOS'!$B$9 -> 0 | U2: ='SUPUESTOS PRECIOS'!$B$5/'SUPUESTOS PRECIOS'!$B$4 -> 1000 | V2: =('SUPUESTOS PRECIOS'!$B$6-'SUPUESTOS PRECIOS'!$B$7)/'SUPUESTOS PRECIOS'!$B$4 -> 377.5 | W2: ='SUPUESTOS PRECIOS'!$B$8 -> 0.00968 | X2: ='SUPUESTOS PRECIOS'!$B$2 -> 0.4 | Y2: =IF(OR($B2="",$J2=""),"",ROUND(($J2+$T2+$U2+$V2)/(1-$W2-$X2),-1)) -> 7920 | Z2: =IF($Y2="","",$Y2-$J2-$T2-$U2-$V2-($Y2*$W2)) -> 3165.8344 | AA2: =IF($Y2="","",$Z2/$Y2) -> 0.39972657
A3: 002 | B3: DET001 | C3: 🍽️ Cocina | D3: Detergente concentrado | E3: bethel | F3: Detergente 30% | G3: sin frangancia | H3: 5 litros | I3: DET001.jpg | J3: 9000 | K3: 0.3 | L3: =IF(J3="","",J3*(1+K3)) -> 11700 | M3: Activo | O3: Activo | P3: NO | Q3: DET001 | R3: Detergente 30%. Presentación: 5 litros. | S3: Detergente concentrado. Ideal para desengrasar y limpiar utensilios, vajilla y superficies de cocina de forma rápida y efectiva. | T3: ='SUPUESTOS PRECIOS'!$B$9 -> 0 | U3: ='SUPUESTOS PRECIOS'!$B$5/'SUPUESTOS PRECIOS'!$B$4 -> 1000 | V3: =('SUPUESTOS PRECIOS'!$B$6-'SUPUESTOS PRECIOS'!$B$7)/'SUPUESTOS PRECIOS'!$B$4 -> 377.5 | W3: ='SUPUESTOS PRECIOS'!$B$8 -> 0.00968 | X3: ='SUPUESTOS PRECIOS'!$B$2 -> 0.4 | Y3: =IF(OR($B3="",$J3=""),"",ROUND(($J3+$T3+$U3+$V3)/(1-$W3-$X3),-1)) -> 17580 | Z3: =IF($Y3="","",$Y3-$J3-$T3-$U3-$V3-($Y3*$W3)) -> 7032.3256 | AA3: =IF($Y3="","",$Z3/$Y3) -> 0.40001852
A4: 003 | B4: LVA001 | C4: 🍽️ Cocina | D4: Detergente listo para usar | E4: bethel | F4: Detergente Magistral listo para usar | G4: sin frangancia | H4: 5 litros | I4: LVA001.jpg | J4: 2750 | K4: 0.3 | L4: =IF(J4="","",J4*(1+K4)) -> 3575 | M4: Activo | O4: Activo | P4: NO | Q4: LVA001 | R4: Detergente Magistral listo para usar. Presentación: 5 litros. | S4: Detergente listo para usar. Ideal para desengrasar y limpiar utensilios, vajilla y superficies de cocina de forma rápida y efectiva. | T4: ='SUPUESTOS PRECIOS'!$B$9 -> 0 | U4: ='SUPUESTOS PRECIOS'!$B$5/'SUPUESTOS PRECIOS'!$B$4 -> 1000 | V4: =('SUPUESTOS PRECIOS'!$B$6-'SUPUESTOS PRECIOS'!$B$7)/'SUPUESTOS PRECIOS'!$B$4 -> 377.5 | W4: ='SUPUESTOS PRECIOS'!$B$8 -> 0.00968 | X4: ='SUPUESTOS PRECIOS'!$B$2 -> 0.4 | Y4: =IF(OR($B4="",$J4=""),"",ROUND(($J4+$T4+$U4+$V4)/(1-$W4-$X4),-1)) -> 6990 | Z4: =IF($Y4="","",$Y4-$J4-$T4-$U4-$V4-($Y4*$W4)) -> 2794.8368 | AA4: =IF($Y4="","",$Z4/$Y4) -> 0.39983359
A5: 004 | B5: LVA002 | C5: 🍽️ Cocina | D5: Lava-vajillas concentrado | E5: bethel | F5: Lava-Vajillas Concentrado | H5: 5 litros | I5: LVA002.jpg | J5: 3250 | K5: 0.3 | L5: =IF(J5="","",J5*(1+K5)) -> 4225 | M5: Activo | O5: Activo | P5: NO | Q5: LVA002 | R5: Lava-Vajillas Concentrado. Presentación: 5 litros. | S5: Lava-vajillas concentrado. Ideal para desengrasar y limpiar utensilios, vajilla y superficies de cocina de forma rápida y efectiva. | T5: ='SUPUESTOS PRECIOS'!$B$9 -> 0 | U5: ='SUPUESTOS PRECIOS'!$B$5/'SUPUESTOS PRECIOS'!$B$4 -> 1000 | V5: =('SUPUESTOS PRECIOS'!$B$6-'SUPUESTOS PRECIOS'!$B$7)/'SUPUESTOS PRECIOS'!$B$4 -> 377.5 | W5: ='SUPUESTOS PRECIOS'!$B$8 -> 0.00968 | X5: ='SUPUESTOS PRECIOS'!$B$2 -> 0.4 | Y5: =IF(OR($B5="",$J5=""),"",ROUND(($J5+$T5+$U5+$V5)/(1-$W5-$X5),-1)) -> 7840 | Z5: =IF($Y5="","",$Y5-$J5-$T5-$U5-$V5-($Y5*$W5)) -> 3136.6088 | AA5: =IF($Y5="","",$Z5/$Y5) -> 0.40007765
A6: 005 | B6: SUA001 | C6: 👕 Ropa y lavado | D6: Suavizante | E6: bethel | F6: Suavizante Blanco por 5 litros | G6: color blanco premium | H6: 5 litros | I6: SUA001.jpg | J6: 5000 | K6: 0.3 | L6: =IF(J6="","",J6*(1+K6)) -> 6500 | M6: Activo | O6: Activo | P6: NO | Q6: SUA001 | R6: Suavizante Blanco por 5 litros. Presentación: 5 litros. Fragancia: color blanco premium. | S6: Suavizante. Cuida las fibras de la ropa, suaviza y deja un aroma agradable y duradero en cada lavado. | T6: ='SUPUESTOS PRECIOS'!$B$9 -> 0 | U6: ='SUPUESTOS PRECIOS'!$B$5/'SUPUESTOS PRECIOS'!$B$4 -> 1000 | V6: =('SUPUESTOS PRECIOS'!$B$6-'SUPUESTOS PRECIOS'!$B$7)/'SUPUESTOS PRECIOS'!$B$4 -> 377.5 | W6: ='SUPUESTOS PRECIOS'!$B$8 -> 0.00968 | X6: ='SUPUESTOS PRECIOS'!$B$2 -> 0.4 | Y6: =IF(OR($B6="",$J6=""),"",ROUND(($J6+$T6+$U6+$V6)/(1-$W6-$X6),-1)) -> 10800 | Z6: =IF($Y6="","",$Y6-$J6-$T6-$U6-$V6-($Y6*$W6)) -> 4317.956 | AA6: =IF($Y6="","",$Z6/$Y6) -> 0.39981074
A7: 006 | B7: SUA002 | C7: 👕 Ropa y lavado | D7: Tradicional | E7: bethel | F7: Suavizante listo para usar | G7: color celeste economico | H7: 5 litros | I7: SUA002.jpg | J7: 4000 | K7: 0.3 | L7: =IF(J7="","",J7*(1+K7)) -> 5200 | M7: Activo | O7: Activo | P7: NO | Q7: SUA002 | R7: Suavizante listo para usar. Presentación: 5 litros. Fragancia: color celeste economico. | S7: Tradicional. Cuida las fibras de la ropa, suaviza y deja un aroma agradable y duradero en cada lavado. | T7: ='SUPUESTOS PRECIOS'!$B$9 -> 0 | U7: ='SUPUESTOS PRECIOS'!$B$5/'SUPUESTOS PRECIOS'!$B$4 -> 1000 | V7: =('SUPUESTOS PRECIOS'!$B$6-'SUPUESTOS PRECIOS'!$B$7)/'SUPUESTOS PRECIOS'!$B$4 -> 377.5 | W7: ='SUPUESTOS PRECIOS'!$B$8 -> 0.00968 | X7: ='SUPUESTOS PRECIOS'!$B$2 -> 0.4 | Y7: =IF(OR($B7="",$J7=""),"",ROUND(($J7+$T7+$U7+$V7)/(1-$W7-$X7),-1)) -> 9110 | Z7: =IF($Y7="","",$Y7-$J7-$T7-$U7-$V7-($Y7*$W7)) -> 3644.3152 | AA7: =IF($Y7="","",$Z7/$Y7) -> 0.4000346
A8: 007 | B8: JBP001 | C8: 👕 Ropa y lavado | D8: Tradicional | E8: granby | F8: Jabon en polvo | H8: 20 kg | I8: JBP001.jpg | J8: 20000 | K8: 0.3 | L8: =IF(J8="","",J8*(1+K8)) -> 26000 | M8: Activo | O8: Activo | P8: NO | Q8: JBP001 | R8: Jabon en polvo. Presentación: 20 kg. Marca granby. | S8: Tradicional. Cuida las fibras de la ropa, suaviza y deja un aroma agradable y duradero en cada lavado. | T8: ='SUPUESTOS PRECIOS'!$B$9 -> 0 | U8: ='SUPUESTOS PRECIOS'!$B$5/'SUPUESTOS PRECIOS'!$B$4 -> 1000 | V8: =('SUPUESTOS PRECIOS'!$B$6-'SUPUESTOS PRECIOS'!$B$7)/'SUPUESTOS PRECIOS'!$B$4 -> 377.5 | W8: ='SUPUESTOS PRECIOS'!$B$8 -> 0.00968 | X8: ='SUPUESTOS PRECIOS'!$B$2 -> 0.4 | Y8: =IF(OR($B8="",$J8=""),"",ROUND(($J8+$T8+$U8+$V8)/(1-$W8-$X8),-1)) -> 36210 | Z8: =IF($Y8="","",$Y8-$J8-$T8-$U8-$V8-($Y8*$W8)) -> 14481.987 | AA8: =IF($Y8="","",$Z8/$Y8) -> 0.39994441
A9: 008 | B9: PFA001 | C9: 🌸 Aromas y fragancias | D9: Perfumes para ropa | E9: bethel | F9: Perfume aromatico de base en agua | G9: 1056, algodón, arpege, bazzu, bebe, c.h.242 , coco, uva, flores blancas, caricias, confy, limon, melon, premium, sandia/frambuesa , softy, ultra, comiglio, vainilla, vivex, flores silvestres, chocolate | H9: 1 litros | I9: PFA001.jpg | J9: 2200 | K9: 0.3 | L9: =IF(J9="","",J9*(1+K9)) -> 2860 | M9: Activo | O9: Activo | P9: NO | Q9: PFA001 | R9: Perfume aromatico de base en agua. Presentación: 1 litros. | S9: Perfumes para ropa. Perfuma ambientes y textiles con una fragancia agradable y duradera, ideal para dejar todo con olor a limpio. Disponible en múltiples fragancias a elección. | T9: ='SUPUESTOS PRECIOS'!$B$9 -> 0 | U9: ='SUPUESTOS PRECIOS'!$B$5/'SUPUESTOS PRECIOS'!$B$4 -> 1000 | V9: =('SUPUESTOS PRECIOS'!$B$6-'SUPUESTOS PRECIOS'!$B$7)/'SUPUESTOS PRECIOS'!$B$4 -> 377.5 | W9: ='SUPUESTOS PRECIOS'!$B$8 -> 0.00968 | X9: ='SUPUESTOS PRECIOS'!$B$2 -> 0.4 | Y9: =IF(OR($B9="",$J9=""),"",ROUND(($J9+$T9+$U9+$V9)/(1-$W9-$X9),-1)) -> 6060 | Z9: =IF($Y9="","",$Y9-$J9-$T9-$U9-$V9-($Y9*$W9)) -> 2423.8392 | AA9: =IF($Y9="","",$Z9/$Y9) -> 0.39997347
A10: 009 | B10: PFA002 | C10: 🌸 Aromas y fragancias | D10: Perfumes para ropa | E10: bethel | F10: Perfume aromatico de base en alcohol | G10: 1056, algodón, arpege, bazzu, bebe, c.h.242 , coco, uva, flores blancas, caricias, confy, limon, melon, premium, sandia/frambuesa , softy, ultra, comiglio, vainilla, vivex, flores silvestres, chocolate | H10: 5 litros | I10: PFA002.jpg | J10: 16000 | K10: 0.3 | L10: =IF(J10="","",J10*(1+K10)) -> 20800 | M10: Activo | O10: Activo | P10: NO | Q10: PFA002 | R10: Perfume aromatico de base en alcohol. Presentación: 5 litros. | S10: Perfumes para ropa. Perfuma ambientes y textiles con una fragancia agradable y duradera, ideal para dejar todo con olor a limpio. Disponible en múltiples fragancias a elección. | T10: ='SUPUESTOS PRECIOS'!$B$9 -> 0 | U10: ='SUPUESTOS PRECIOS'!$B$5/'SUPUESTOS PRECIOS'!$B$4 -> 1000 | V10: =('SUPUESTOS PRECIOS'!$B$6-'SUPUESTOS PRECIOS'!$B$7)/'SUPUESTOS PRECIOS'!$B$4 -> 377.5 | W10: ='SUPUESTOS PRECIOS'!$B$8 -> 0.00968 | X10: ='SUPUESTOS PRECIOS'!$B$2 -> 0.4 | Y10: =IF(OR($B10="",$J10=""),"",ROUND(($J10+$T10+$U10+$V10)/(1-$W10-$X10),-1)) -> 29440 | Z10: =IF($Y10="","",$Y10-$J10-$T10-$U10-$V10-($Y10*$W10)) -> 11777.521 | AA10: =IF($Y10="","",$Z10/$Y10) -> 0.40005166
A11: 010 | B11: DES001 | C11: 🦠 Desinfección y limpieza | D11: Desengrasantes | E11: bethel | F11: Desengrasante industrial | H11: 5 litros | I11: DES001.jpg | J11: 4600 | K11: 0.3 | L11: =IF(J11="","",J11*(1+K11)) -> 5980 | M11: Activo | O11: Activo | P11: NO | Q11: DES001 | R11: Desengrasante industrial. Presentación: 5 litros. | S11: Desengrasantes. Elimina bacterias y gérmenes, desinfectando a fondo superficies del hogar, comercios e industrias. | T11: ='SUPUESTOS PRECIOS'!$B$9 -> 0 | U11: ='SUPUESTOS PRECIOS'!$B$5/'SUPUESTOS PRECIOS'!$B$4 -> 1000 | V11: =('SUPUESTOS PRECIOS'!$B$6-'SUPUESTOS PRECIOS'!$B$7)/'SUPUESTOS PRECIOS'!$B$4 -> 377.5 | W11: ='SUPUESTOS PRECIOS'!$B$8 -> 0.00968 | X11: ='SUPUESTOS PRECIOS'!$B$2 -> 0.4 | Y11: =IF(OR($B11="",$J11=""),"",ROUND(($J11+$T11+$U11+$V11)/(1-$W11-$X11),-1)) -> 10130 | Z11: =IF($Y11="","",$Y11-$J11-$T11-$U11-$V11-($Y11*$W11)) -> 4054.4416 | AA11: =IF($Y11="","",$Z11/$Y11) -> 0.40024103
A12: 011 | B12: DES002 | C12: 🦠 Desinfección y limpieza | D12: Desengrasantes | E12: bethel | F12: Desengrasante lavamotor | H12: 5 litros | I12: DES002.jpg | J12: 5400 | K12: 0.3 | L12: =IF(J12="","",J12*(1+K12)) -> 7020 | M12: Activo | O12: Activo | P12: NO | Q12: DES002 | R12: Desengrasante lavamotor. Presentación: 5 litros. | S12: Desengrasantes. Elimina bacterias y gérmenes, desinfectando a fondo superficies del hogar, comercios e industrias. | T12: ='SUPUESTOS PRECIOS'!$B$9 -> 0 | U12: ='SUPUESTOS PRECIOS'!$B$5/'SUPUESTOS PRECIOS'!$B$4 -> 1000 | V12: =('SUPUESTOS PRECIOS'!$B$6-'SUPUESTOS PRECIOS'!$B$7)/'SUPUESTOS PRECIOS'!$B$4 -> 377.5 | W12: ='SUPUESTOS PRECIOS'!$B$8 -> 0.00968 | X12: ='SUPUESTOS PRECIOS'!$B$2 -> 0.4 | Y12: =IF(OR($B12="",$J12=""),"",ROUND(($J12+$T12+$U12+$V12)/(1-$W12-$X12),-1)) -> 11480 | Z12: =IF($Y12="","",$Y12-$J12-$T12-$U12-$V12-($Y12*$W12)) -> 4591.3736 | AA12: =IF($Y12="","",$Z12/$Y12) -> 0.39994544
A13: 012 | B13: DES003 | C13: 🦠 Desinfección y limpieza | D13: Desengrasantes | E13: bethel | F13: Desengrasante multi usos | H13: 5 litros | I13: DES003.jpg | J13: 5400 | K13: 0.3 | L13: =IF(J13="","",J13*(1+K13)) -> 7020 | M13: Activo | O13: Activo | P13: NO | Q13: DES003 | R13: Desengrasante multi usos. Presentación: 5 litros. | S13: Desengrasantes. Elimina bacterias y gérmenes, desinfectando a fondo superficies del hogar, comercios e industrias. | T13: ='SUPUESTOS PRECIOS'!$B$9 -> 0 | U13: ='SUPUESTOS PRECIOS'!$B$5/'SUPUESTOS PRECIOS'!$B$4 -> 1000 | V13: =('SUPUESTOS PRECIOS'!$B$6-'SUPUESTOS PRECIOS'!$B$7)/'SUPUESTOS PRECIOS'!$B$4 -> 377.5 | W13: ='SUPUESTOS PRECIOS'!$B$8 -> 0.00968 | X13: ='SUPUESTOS PRECIOS'!$B$2 -> 0.4 | Y13: =IF(OR($B13="",$J13=""),"",ROUND(($J13+$T13+$U13+$V13)/(1-$W13-$X13),-1)) -> 11480 | Z13: =IF($Y13="","",$Y13-$J13-$T13-$U13-$V13-($Y13*$W13)) -> 4591.3736 | AA13: =IF($Y13="","",$Z13/$Y13) -> 0.39994544
A14: 013 | B14: DES004 | C14: 🦠 Desinfección y limpieza | D14: Desengrasantes | E14: bethel | F14: Desengrasante quima manchas | H14: 5 litros | I14: DES004.jpg | J14: 5400 | K14: 0.3 | L14: =IF(J14="","",J14*(1+K14)) -> 7020 | M14: Activo | O14: Activo | P14: NO | Q14: DES004 | R14: Desengrasante quima manchas. Presentación: 5 litros. | S14: Desengrasantes. Elimina bacterias y gérmenes, desinfectando a fondo superficies del hogar, comercios e industrias. | T14: ='SUPUESTOS PRECIOS'!$B$9 -> 0 | U14: ='SUPUESTOS PRECIOS'!$B$5/'SUPUESTOS PRECIOS'!$B$4 -> 1000 | V14: =('SUPUESTOS PRECIOS'!$B$6-'SUPUESTOS PRECIOS'!$B$7)/'SUPUESTOS PRECIOS'!$B$4 -> 377.5 | W14: ='SUPUESTOS PRECIOS'!$B$8 -> 0.00968 | X14: ='SUPUESTOS PRECIOS'!$B$2 -> 0.4 | Y14: =IF(OR($B14="",$J14=""),"",ROUND(($J14+$T14+$U14+$V14)/(1-$W14-$X14),-1)) -> 11480 | Z14: =IF($Y14="","",$Y14-$J14-$T14-$U14-$V14-($Y14*$W14)) -> 4591.3736 | AA14: =IF($Y14="","",$Z14/$Y14) -> 0.39994544
A15: 014 | B15: DES005 | C15: 🦠 Desinfección y limpieza | D15: Desengrasantes | E15: bethel | F15: Desengrasante limpiador cremoso | H15: 5 litros | I15: DES005.jpg | J15: 7300 | K15: 0.3 | L15: =IF(J15="","",J15*(1+K15)) -> 9490 | M15: Activo | O15: Activo | P15: NO | Q15: DES005 | R15: Desengrasante limpiador cremoso. Presentación: 5 litros. | S15: Desengrasantes. Elimina bacterias y gérmenes, desinfectando a fondo superficies del hogar, comercios e industrias. | T15: ='SUPUESTOS PRECIOS'!$B$9 -> 0 | U15: ='SUPUESTOS PRECIOS'!$B$5/'SUPUESTOS PRECIOS'!$B$4 -> 1000 | V15: =('SUPUESTOS PRECIOS'!$B$6-'SUPUESTOS PRECIOS'!$B$7)/'SUPUESTOS PRECIOS'!$B$4 -> 377.5 | W15: ='SUPUESTOS PRECIOS'!$B$8 -> 0.00968 | X15: ='SUPUESTOS PRECIOS'!$B$2 -> 0.4 | Y15: =IF(OR($B15="",$J15=""),"",ROUND(($J15+$T15+$U15+$V15)/(1-$W15-$X15),-1)) -> 14700 | Z15: =IF($Y15="","",$Y15-$J15-$T15-$U15-$V15-($Y15*$W15)) -> 5880.204 | AA15: =IF($Y15="","",$Z15/$Y15) -> 0.40001388
A16: 015 | B16: RJR001 | C16: 🧰 Accesorios y equipamiento | D16: Rejillas y repasadores | E16: bethel | F16: Franela 40x50 | H16: 1 unidad | I16: RJR001.jpg | J16: 700 | K16: 0.3 | L16: =IF(J16="","",J16*(1+K16)) -> 910 | M16: Activo | O16: Activo | P16: NO | Q16: RJR001 | R16: Franela 40x50. Presentación: 1 unidad. | S16: Rejillas y repasadores. Accesorio resistente y práctico, pensado para facilitar las tareas de limpieza del hogar. | T16: ='SUPUESTOS PRECIOS'!$B$9 -> 0 | U16: ='SUPUESTOS PRECIOS'!$B$5/'SUPUESTOS PRECIOS'!$B$4 -> 1000 | V16: =('SUPUESTOS PRECIOS'!$B$6-'SUPUESTOS PRECIOS'!$B$7)/'SUPUESTOS PRECIOS'!$B$4 -> 377.5 | W16: ='SUPUESTOS PRECIOS'!$B$8 -> 0.00968 | X16: ='SUPUESTOS PRECIOS'!$B$2 -> 0.4 | Y16: =IF(OR($B16="",$J16=""),"",ROUND(($J16+$T16+$U16+$V16)/(1-$W16-$X16),-1)) -> 3520 | Z16: =IF($Y16="","",$Y16-$J16-$T16-$U16-$V16-($Y16*$W16)) -> 1408.4264 | AA16: =IF($Y16="","",$Z16/$Y16) -> 0.40012114
A17: 016 | B17: RJR002 | C17: 🧰 Accesorios y equipamiento | D17: Rejillas y repasadores | E17: bethel | F17: Rejilla de cocina | H17: 1 unidad | I17: RJR002.jpg | J17: 300 | K17: 0.3 | L17: =IF(J17="","",J17*(1+K17)) -> 390 | M17: Activo | O17: Activo | P17: NO | Q17: RJR002 | R17: Rejilla de cocina. Presentación: 1 unidad. | S17: Rejillas y repasadores. Accesorio resistente y práctico, pensado para facilitar las tareas de limpieza del hogar. | T17: ='SUPUESTOS PRECIOS'!$B$9 -> 0 | U17: ='SUPUESTOS PRECIOS'!$B$5/'SUPUESTOS PRECIOS'!$B$4 -> 1000 | V17: =('SUPUESTOS PRECIOS'!$B$6-'SUPUESTOS PRECIOS'!$B$7)/'SUPUESTOS PRECIOS'!$B$4 -> 377.5 | W17: ='SUPUESTOS PRECIOS'!$B$8 -> 0.00968 | X17: ='SUPUESTOS PRECIOS'!$B$2 -> 0.4 | Y17: =IF(OR($B17="",$J17=""),"",ROUND(($J17+$T17+$U17+$V17)/(1-$W17-$X17),-1)) -> 2840 | Z17: =IF($Y17="","",$Y17-$J17-$T17-$U17-$V17-($Y17*$W17)) -> 1135.0088 | AA17: =IF($Y17="","",$Z17/$Y17) -> 0.39965099
A18: 017 | B18: RJR003 | C18: 🧰 Accesorios y equipamiento | D18: Rejillas y repasadores | E18: bethel | F18: Rejilla tipo americana | H18: 1 unidad | I18: RJR003.jpg | J18: 500 | K18: 0.3 | L18: =IF(J18="","",J18*(1+K18)) -> 650 | M18: Activo | O18: Activo | P18: NO | Q18: RJR003 | R18: Rejilla tipo americana. Presentación: 1 unidad. | S18: Rejillas y repasadores. Accesorio resistente y práctico, pensado para facilitar las tareas de limpieza del hogar. | T18: ='SUPUESTOS PRECIOS'!$B$9 -> 0 | U18: ='SUPUESTOS PRECIOS'!$B$5/'SUPUESTOS PRECIOS'!$B$4 -> 1000 | V18: =('SUPUESTOS PRECIOS'!$B$6-'SUPUESTOS PRECIOS'!$B$7)/'SUPUESTOS PRECIOS'!$B$4 -> 377.5 | W18: ='SUPUESTOS PRECIOS'!$B$8 -> 0.00968 | X18: ='SUPUESTOS PRECIOS'!$B$2 -> 0.4 | Y18: =IF(OR($B18="",$J18=""),"",ROUND(($J18+$T18+$U18+$V18)/(1-$W18-$X18),-1)) -> 3180 | Z18: =IF($Y18="","",$Y18-$J18-$T18-$U18-$V18-($Y18*$W18)) -> 1271.7176 | AA18: =IF($Y18="","",$Z18/$Y18) -> 0.39991119
A19: 018 | B19: RJR004 | C19: 🧰 Accesorios y equipamiento | D19: Rejillas y repasadores | E19: bethel | F19: Rejilla de auto | H19: 1 unidad | I19: RJR004.jpg | J19: 500 | K19: 0.3 | L19: =IF(J19="","",J19*(1+K19)) -> 650 | M19: Activo | O19: Activo | P19: NO | Q19: RJR004 | R19: Rejilla de auto. Presentación: 1 unidad. | S19: Rejillas y repasadores. Accesorio resistente y práctico, pensado para facilitar las tareas de limpieza del hogar. | T19: ='SUPUESTOS PRECIOS'!$B$9 -> 0 | U19: ='SUPUESTOS PRECIOS'!$B$5/'SUPUESTOS PRECIOS'!$B$4 -> 1000 | V19: =('SUPUESTOS PRECIOS'!$B$6-'SUPUESTOS PRECIOS'!$B$7)/'SUPUESTOS PRECIOS'!$B$4 -> 377.5 | W19: ='SUPUESTOS PRECIOS'!$B$8 -> 0.00968 | X19: ='SUPUESTOS PRECIOS'!$B$2 -> 0.4 | Y19: =IF(OR($B19="",$J19=""),"",ROUND(($J19+$T19+$U19+$V19)/(1-$W19-$X19),-1)) -> 3180 | Z19: =IF($Y19="","",$Y19-$J19-$T19-$U19-$V19-($Y19*$W19)) -> 1271.7176 | AA19: =IF($Y19="","",$Z19/$Y19) -> 0.39991119 | AB19: RJR-AUTO | AC19: SIMPLE
A20: 019 | B20: RJR005 | C20: 🧰 Accesorios y equipamiento | D20: Rejillas y repasadores | E20: bethel | F20: Rejilla de pabilo | H20: 1 unidad | I20: RJR005.jpg | J20: 500 | K20: 0.3 | L20: =IF(J20="","",J20*(1+K20)) -> 650 | M20: Activo | O20: Activo | P20: NO | Q20: RJR005 | R20: Rejilla de pabilo. Presentación: 1 unidad. | S20: Rejillas y repasadores. Accesorio resistente y práctico, pensado para facilitar las tareas de limpieza del hogar. | T20: ='SUPUESTOS PRECIOS'!$B$9 -> 0 | U20: ='SUPUESTOS PRECIOS'!$B$5/'SUPUESTOS PRECIOS'!$B$4 -> 1000 | V20: =('SUPUESTOS PRECIOS'!$B$6-'SUPUESTOS PRECIOS'!$B$7)/'SUPUESTOS PRECIOS'!$B$4 -> 377.5 | W20: ='SUPUESTOS PRECIOS'!$B$8 -> 0.00968 | X20: ='SUPUESTOS PRECIOS'!$B$2 -> 0.4 | Y20: =IF(OR($B20="",$J20=""),"",ROUND(($J20+$T20+$U20+$V20)/(1-$W20-$X20),-1)) -> 3180 | Z20: =IF($Y20="","",$Y20-$J20-$T20-$U20-$V20-($Y20*$W20)) -> 1271.7176 | AA20: =IF($Y20="","",$Z20/$Y20) -> 0.39991119
A21: 020 | B21: RJR006 | C21: 🧰 Accesorios y equipamiento | D21: Rejillas y repasadores | E21: bethel | F21: Rejilla de auto | H21: 1 unidad | I21: RJR006.jpg | J21: 2050 | K21: 0.3 | L21: =IF(J21="","",J21*(1+K21)) -> 2665 | M21: Activo | O21: Activo | P21: NO | Q21: RJR006 | R21: Rejilla de auto. Presentación: 1 unidad. | S21: Rejillas y repasadores. Accesorio resistente y práctico, pensado para facilitar las tareas de limpieza del hogar. | T21: ='SUPUESTOS PRECIOS'!$B$9 -> 0 | U21: ='SUPUESTOS PRECIOS'!$B$5/'SUPUESTOS PRECIOS'!$B$4 -> 1000 | V21: =('SUPUESTOS PRECIOS'!$B$6-'SUPUESTOS PRECIOS'!$B$7)/'SUPUESTOS PRECIOS'!$B$4 -> 377.5 | W21: ='SUPUESTOS PRECIOS'!$B$8 -> 0.00968 | X21: ='SUPUESTOS PRECIOS'!$B$2 -> 0.4 | Y21: =IF(OR($B21="",$J21=""),"",ROUND(($J21+$T21+$U21+$V21)/(1-$W21-$X21),-1)) -> 5810 | Z21: =IF($Y21="","",$Y21-$J21-$T21-$U21-$V21-($Y21*$W21)) -> 2326.2592 | AA21: =IF($Y21="","",$Z21/$Y21) -> 0.40038885 | AB21: RJR-AUTO | AC21: DOBLE
A22: 021 | B22: RJR007 | C22: 🧰 Accesorios y equipamiento | D22: Rejillas y repasadores | E22: bethel | F22: Rejilla de auto | H22: 1 unidad | I22: RJR007.jpg | J22: 2050 | K22: 0.3 | L22: =IF(J22="","",J22*(1+K22)) -> 2665 | M22: Activo | O22: Activo | P22: NO | Q22: RJR007 | R22: Rejilla de auto. Presentación: 1 unidad. | S22: Rejillas y repasadores. Accesorio resistente y práctico, pensado para facilitar las tareas de limpieza del hogar. | T22: ='SUPUESTOS PRECIOS'!$B$9 -> 0 | U22: ='SUPUESTOS PRECIOS'!$B$5/'SUPUESTOS PRECIOS'!$B$4 -> 1000 | V22: =('SUPUESTOS PRECIOS'!$B$6-'SUPUESTOS PRECIOS'!$B$7)/'SUPUESTOS PRECIOS'!$B$4 -> 377.5 | W22: ='SUPUESTOS PRECIOS'!$B$8 -> 0.00968 | X22: ='SUPUESTOS PRECIOS'!$B$2 -> 0.4 | Y22: =IF(OR($B22="",$J22=""),"",ROUND(($J22+$T22+$U22+$V22)/(1-$W22-$X22),-1)) -> 5810 | Z22: =IF($Y22="","",$Y22-$J22-$T22-$U22-$V22-($Y22*$W22)) -> 2326.2592 | AA22: =IF($Y22="","",$Z22/$Y22) -> 0.40038885 | AB22: RJR-AUTO | AC22: TRIPLE
A23: 022 | B23: RJR008 | C23: 🧰 Accesorios y equipamiento | D23: Rejillas y repasadores | E23: bethel | F23: Rejilla cocina | H23: 1 unidad | I23: RJR008.jpg | J23: 750 | K23: 0.3 | L23: =IF(J23="","",J23*(1+K23)) -> 975 | M23: Activo | O23: Activo | P23: NO | Q23: RJR008 | R23: Rejilla cocina. Presentación: 1 unidad. | S23: Rejillas y repasadores. Accesorio resistente y práctico, pensado para facilitar las tareas de limpieza del hogar. | T23: ='SUPUESTOS PRECIOS'!$B$9 -> 0 | U23: ='SUPUESTOS PRECIOS'!$B$5/'SUPUESTOS PRECIOS'!$B$4 -> 1000 | V23: =('SUPUESTOS PRECIOS'!$B$6-'SUPUESTOS PRECIOS'!$B$7)/'SUPUESTOS PRECIOS'!$B$4 -> 377.5 | W23: ='SUPUESTOS PRECIOS'!$B$8 -> 0.00968 | X23: ='SUPUESTOS PRECIOS'!$B$2 -> 0.4 | Y23: =IF(OR($B23="",$J23=""),"",ROUND(($J23+$T23+$U23+$V23)/(1-$W23-$X23),-1)) -> 3600 | Z23: =IF($Y23="","",$Y23-$J23-$T23-$U23-$V23-($Y23*$W23)) -> 1437.652 | AA23: =IF($Y23="","",$Z23/$Y23) -> 0.39934778 | AB23: RJR-COCINA | AC23: TRIPLE
A24: 023 | B24: RJR009 | C24: 🧰 Accesorios y equipamiento | D24: Rejillas y repasadores | E24: Kide | F24: Rejilla cocina | H24: 1 unidad | I24: RJR009.jpg | J24: 650 | K24: 0.3 | L24: =IF(J24="","",J24*(1+K24)) -> 845 | M24: Activo | O24: Activo | P24: NO | Q24: RJR009 | R24: Rejilla cocina. Presentación: 1 unidad. Marca Kide. | S24: Rejillas y repasadores. Accesorio resistente y práctico, pensado para facilitar las tareas de limpieza del hogar. | T24: ='SUPUESTOS PRECIOS'!$B$9 -> 0 | U24: ='SUPUESTOS PRECIOS'!$B$5/'SUPUESTOS PRECIOS'!$B$4 -> 1000 | V24: =('SUPUESTOS PRECIOS'!$B$6-'SUPUESTOS PRECIOS'!$B$7)/'SUPUESTOS PRECIOS'!$B$4 -> 377.5 | W24: ='SUPUESTOS PRECIOS'!$B$8 -> 0.00968 | X24: ='SUPUESTOS PRECIOS'!$B$2 -> 0.4 | Y24: =IF(OR($B24="",$J24=""),"",ROUND(($J24+$T24+$U24+$V24)/(1-$W24-$X24),-1)) -> 3430 | Z24: =IF($Y24="","",$Y24-$J24-$T24-$U24-$V24-($Y24*$W24)) -> 1369.2976 | AA24: =IF($Y24="","",$Z24/$Y24) -> 0.39921213 | AB24: RJR-COCINA | AC24: DOBLE
A25: 024 | B25: RJR010 | C25: 🧰 Accesorios y equipamiento | D25: Rejillas y repasadores | E25: bethel | F25: Rejilla pabilo | H25: 1 unidad | I25: RJR010.jpg | J25: 260 | K25: 0.3 | L25: =IF(J25="","",J25*(1+K25)) -> 338 | M25: Activo | O25: Activo | P25: NO | Q25: RJR011 | R25: Rejilla pabilo. Presentación: 1 unidad. | S25: Rejillas y repasadores. Accesorio resistente y práctico, pensado para facilitar las tareas de limpieza del hogar. | T25: ='SUPUESTOS PRECIOS'!$B$9 -> 0 | U25: ='SUPUESTOS PRECIOS'!$B$5/'SUPUESTOS PRECIOS'!$B$4 -> 1000 | V25: =('SUPUESTOS PRECIOS'!$B$6-'SUPUESTOS PRECIOS'!$B$7)/'SUPUESTOS PRECIOS'!$B$4 -> 377.5 | W25: ='SUPUESTOS PRECIOS'!$B$8 -> 0.00968 | X25: ='SUPUESTOS PRECIOS'!$B$2 -> 0.4 | Y25: =IF(OR($B25="",$J25=""),"",ROUND(($J25+$T25+$U25+$V25)/(1-$W25-$X25),-1)) -> 2770 | Z25: =IF($Y25="","",$Y25-$J25-$T25-$U25-$V25-($Y25*$W25)) -> 1105.6864 | AA25: =IF($Y25="","",$Z25/$Y25) -> 0.39916477
A26: 025 | B26: RJR011 | C26: 🧰 Accesorios y equipamiento | D26: Rejillas y repasadores | E26: bethel | F26: Rejilla pabilo | H26: 1 unidad | I26: RJR011.jpg | J26: 300 | K26: 0.3 | L26: =IF(J26="","",J26*(1+K26)) -> 390 | M26: Activo | O26: Activo | P26: NO | Q26: RJR012 | R26: Rejilla pabilo. Presentación: 1 unidad. | S26: Rejillas y repasadores. Accesorio resistente y práctico, pensado para facilitar las tareas de limpieza del hogar. | T26: ='SUPUESTOS PRECIOS'!$B$9 -> 0 | U26: ='SUPUESTOS PRECIOS'!$B$5/'SUPUESTOS PRECIOS'!$B$4 -> 1000 | V26: =('SUPUESTOS PRECIOS'!$B$6-'SUPUESTOS PRECIOS'!$B$7)/'SUPUESTOS PRECIOS'!$B$4 -> 377.5 | W26: ='SUPUESTOS PRECIOS'!$B$8 -> 0.00968 | X26: ='SUPUESTOS PRECIOS'!$B$2 -> 0.4 | Y26: =IF(OR($B26="",$J26=""),"",ROUND(($J26+$T26+$U26+$V26)/(1-$W26-$X26),-1)) -> 2840 | Z26: =IF($Y26="","",$Y26-$J26-$T26-$U26-$V26-($Y26*$W26)) -> 1135.0088 | AA26: =IF($Y26="","",$Z26/$Y26) -> 0.39965099
A27: 026 | B27: RJR012 | C27: 🧰 Accesorios y equipamiento | D27: Rejillas y repasadores | E27: bethel | F27: Rejilla cocina | H27: 1 unidad | I27: RJR012.jpg | J27: 300 | K27: 0.3 | L27: =IF(J27="","",J27*(1+K27)) -> 390 | M27: Activo | O27: Activo | P27: NO | Q27: RJR013 | R27: Rejilla cocina. Presentación: 1 unidad. | S27: Rejillas y repasadores. Accesorio resistente y práctico, pensado para facilitar las tareas de limpieza del hogar. | T27: ='SUPUESTOS PRECIOS'!$B$9 -> 0 | U27: ='SUPUESTOS PRECIOS'!$B$5/'SUPUESTOS PRECIOS'!$B$4 -> 1000 | V27: =('SUPUESTOS PRECIOS'!$B$6-'SUPUESTOS PRECIOS'!$B$7)/'SUPUESTOS PRECIOS'!$B$4 -> 377.5 | W27: ='SUPUESTOS PRECIOS'!$B$8 -> 0.00968 | X27: ='SUPUESTOS PRECIOS'!$B$2 -> 0.4 | Y27: =IF(OR($B27="",$J27=""),"",ROUND(($J27+$T27+$U27+$V27)/(1-$W27-$X27),-1)) -> 2840 | Z27: =IF($Y27="","",$Y27-$J27-$T27-$U27-$V27-($Y27*$W27)) -> 1135.0088 | AA27: =IF($Y27="","",$Z27/$Y27) -> 0.39965099 | AB27: RJR-COCINA | AC27: SIMPLE
A28: 027 | B28: RJR013 | C28: 🧰 Accesorios y equipamiento | D28: Rejillas y repasadores | E28: bethel | F28: Repasador | H28: 1 unidad | I28: RJR013.jpg | J28: 1100 | K28: 0.3 | L28: =IF(J28="","",J28*(1+K28)) -> 1430 | M28: Activo | O28: Activo | P28: NO | Q28: RJR014 | R28: Repasador. Presentación: 1 unidad. | S28: Rejillas y repasadores. Accesorio resistente y práctico, pensado para facilitar las tareas de limpieza del hogar. | T28: ='SUPUESTOS PRECIOS'!$B$9 -> 0 | U28: ='SUPUESTOS PRECIOS'!$B$5/'SUPUESTOS PRECIOS'!$B$4 -> 1000 | V28: =('SUPUESTOS PRECIOS'!$B$6-'SUPUESTOS PRECIOS'!$B$7)/'SUPUESTOS PRECIOS'!$B$4 -> 377.5 | W28: ='SUPUESTOS PRECIOS'!$B$8 -> 0.00968 | X28: ='SUPUESTOS PRECIOS'!$B$2 -> 0.4 | Y28: =IF(OR($B28="",$J28=""),"",ROUND(($J28+$T28+$U28+$V28)/(1-$W28-$X28),-1)) -> 4200 | Z28: =IF($Y28="","",$Y28-$J28-$T28-$U28-$V28-($Y28*$W28)) -> 1681.844 | AA28: =IF($Y28="","",$Z28/$Y28) -> 0.40043905
A29: 028 | B29: RJR014 | C29: 🧰 Accesorios y equipamiento | D29: Rejillas y repasadores | E29: bethel | F29: Repasador | H29: 1 unidad | I29: RJR014.jpg | J29: 1700 | K29: 0.3 | L29: =IF(J29="","",J29*(1+K29)) -> 2210 | M29: Activo | O29: Activo | P29: NO | Q29: RJR015-REPASADOR | R29: Repasador. Presentación: 1 unidad. | S29: Rejillas y repasadores. Accesorio resistente y práctico, pensado para facilitar las tareas de limpieza del hogar. | T29: ='SUPUESTOS PRECIOS'!$B$9 -> 0 | U29: ='SUPUESTOS PRECIOS'!$B$5/'SUPUESTOS PRECIOS'!$B$4 -> 1000 | V29: =('SUPUESTOS PRECIOS'!$B$6-'SUPUESTOS PRECIOS'!$B$7)/'SUPUESTOS PRECIOS'!$B$4 -> 377.5 | W29: ='SUPUESTOS PRECIOS'!$B$8 -> 0.00968 | X29: ='SUPUESTOS PRECIOS'!$B$2 -> 0.4 | Y29: =IF(OR($B29="",$J29=""),"",ROUND(($J29+$T29+$U29+$V29)/(1-$W29-$X29),-1)) -> 5210 | Z29: =IF($Y29="","",$Y29-$J29-$T29-$U29-$V29-($Y29*$W29)) -> 2082.0672 | AA29: =IF($Y29="","",$Z29/$Y29) -> 0.39962902
A30: 029 | B30: RJR015 | C30: 🧰 Accesorios y equipamiento | D30: Rejillas y repasadores | E30: bethel | F30: Paño amarillo para piso | H30: 1 unidad | I30: RJR015.jpg | J30: 600 | K30: 0.3 | L30: =IF(J30="","",J30*(1+K30)) -> 780 | M30: Activo | O30: Activo | P30: NO | Q30: RJR015 | R30: Paño amarillo para piso. Presentación: 1 unidad. | S30: Rejillas y repasadores. Accesorio resistente y práctico, pensado para facilitar las tareas de limpieza del hogar. | T30: ='SUPUESTOS PRECIOS'!$B$9 -> 0 | U30: ='SUPUESTOS PRECIOS'!$B$5/'SUPUESTOS PRECIOS'!$B$4 -> 1000 | V30: =('SUPUESTOS PRECIOS'!$B$6-'SUPUESTOS PRECIOS'!$B$7)/'SUPUESTOS PRECIOS'!$B$4 -> 377.5 | W30: ='SUPUESTOS PRECIOS'!$B$8 -> 0.00968 | X30: ='SUPUESTOS PRECIOS'!$B$2 -> 0.4 | Y30: =IF(OR($B30="",$J30=""),"",ROUND(($J30+$T30+$U30+$V30)/(1-$W30-$X30),-1)) -> 3350 | Z30: =IF($Y30="","",$Y30-$J30-$T30-$U30-$V30-($Y30*$W30)) -> 1340.072 | AA30: =IF($Y30="","",$Z30/$Y30) -> 0.40002149
A31: 030 | B31: TDP001 | C31: 🧰 Accesorios y equipamiento | D31: Trapos de piso | E31: bethel | F31: Trapo de piso blanco | H31: 1 unidad | I31: TDP001.jpg | J31: 1150 | K31: 0.3 | L31: =IF(J31="","",J31*(1+K31)) -> 1495 | M31: Activo | O31: Activo | P31: NO | Q31: TDP001 | R31: Trapo de piso blanco. Presentación: 1 unidad. | S31: Trapos de piso. Accesorio resistente y práctico, pensado para facilitar las tareas de limpieza del hogar. | T31: ='SUPUESTOS PRECIOS'!$B$9 -> 0 | U31: ='SUPUESTOS PRECIOS'!$B$5/'SUPUESTOS PRECIOS'!$B$4 -> 1000 | V31: =('SUPUESTOS PRECIOS'!$B$6-'SUPUESTOS PRECIOS'!$B$7)/'SUPUESTOS PRECIOS'!$B$4 -> 377.5 | W31: ='SUPUESTOS PRECIOS'!$B$8 -> 0.00968 | X31: ='SUPUESTOS PRECIOS'!$B$2 -> 0.4 | Y31: =IF(OR($B31="",$J31=""),"",ROUND(($J31+$T31+$U31+$V31)/(1-$W31-$X31),-1)) -> 4280 | Z31: =IF($Y31="","",$Y31-$J31-$T31-$U31-$V31-($Y31*$W31)) -> 1711.0696 | AA31: =IF($Y31="","",$Z31/$Y31) -> 0.39978262
A32: 031 | B32: TDP002 | C32: 🧰 Accesorios y equipamiento | D32: Trapos de piso | E32: bethel | F32: Trapo de piso gris | H32: 1 unidad | I32: TDP002.jpg | J32: 1150 | K32: 0.3 | L32: =IF(J32="","",J32*(1+K32)) -> 1495 | M32: Activo | O32: Activo | P32: NO | Q32: TDP002 | R32: Trapo de piso gris. Presentación: 1 unidad. | S32: Trapos de piso. Accesorio resistente y práctico, pensado para facilitar las tareas de limpieza del hogar. | T32: ='SUPUESTOS PRECIOS'!$B$9 -> 0 | U32: ='SUPUESTOS PRECIOS'!$B$5/'SUPUESTOS PRECIOS'!$B$4 -> 1000 | V32: =('SUPUESTOS PRECIOS'!$B$6-'SUPUESTOS PRECIOS'!$B$7)/'SUPUESTOS PRECIOS'!$B$4 -> 377.5 | W32: ='SUPUESTOS PRECIOS'!$B$8 -> 0.00968 | X32: ='SUPUESTOS PRECIOS'!$B$2 -> 0.4 | Y32: =IF(OR($B32="",$J32=""),"",ROUND(($J32+$T32+$U32+$V32)/(1-$W32-$X32),-1)) -> 4280 | Z32: =IF($Y32="","",$Y32-$J32-$T32-$U32-$V32-($Y32*$W32)) -> 1711.0696 | AA32: =IF($Y32="","",$Z32/$Y32) -> 0.39978262
A33: 032 | B33: TDP003 | C33: 🧰 Accesorios y equipamiento | D33: Trapos de piso | E33: mr trappo | F33: Trapo de piso costurado | H33: 1 unidad | I33: TDP003.jpg | J33: 1000 | K33: 0.3 | L33: =IF(J33="","",J33*(1+K33)) -> 1300 | M33: Activo | O33: Activo | P33: NO | Q33: TDP003 | R33: Trapo de piso costurado. Presentación: 1 unidad. Marca mr trappo. | S33: Trapos de piso. Accesorio resistente y práctico, pensado para facilitar las tareas de limpieza del hogar. | T33: ='SUPUESTOS PRECIOS'!$B$9 -> 0 | U33: ='SUPUESTOS PRECIOS'!$B$5/'SUPUESTOS PRECIOS'!$B$4 -> 1000 | V33: =('SUPUESTOS PRECIOS'!$B$6-'SUPUESTOS PRECIOS'!$B$7)/'SUPUESTOS PRECIOS'!$B$4 -> 377.5 | W33: ='SUPUESTOS PRECIOS'!$B$8 -> 0.00968 | X33: ='SUPUESTOS PRECIOS'!$B$2 -> 0.4 | Y33: =IF(OR($B33="",$J33=""),"",ROUND(($J33+$T33+$U33+$V33)/(1-$W33-$X33),-1)) -> 4030 | Z33: =IF($Y33="","",$Y33-$J33-$T33-$U33-$V33-($Y33*$W33)) -> 1613.4896 | AA33: =IF($Y33="","",$Z33/$Y33) -> 0.40036963 | AB33: TDP-COSTURADO | AC33: DOBLE
A34: 033 | B34: TDP004 | C34: 🧰 Accesorios y equipamiento | D34: Trapos de piso | E34: Fibran | F34: Trapo de piso costurado | H34: 1 unidad | I34: TDP004.jpg | J34: 650 | K34: 0.3 | L34: =IF(J34="","",J34*(1+K34)) -> 845 | M34: Activo | O34: Activo | P34: NO | Q34: TDP004 | R34: Trapo de piso costurado. Presentación: 1 unidad. Marca Fibran. | S34: Trapos de piso. Accesorio resistente y práctico, pensado para facilitar las tareas de limpieza del hogar. | T34: ='SUPUESTOS PRECIOS'!$B$9 -> 0 | U34: ='SUPUESTOS PRECIOS'!$B$5/'SUPUESTOS PRECIOS'!$B$4 -> 1000 | V34: =('SUPUESTOS PRECIOS'!$B$6-'SUPUESTOS PRECIOS'!$B$7)/'SUPUESTOS PRECIOS'!$B$4 -> 377.5 | W34: ='SUPUESTOS PRECIOS'!$B$8 -> 0.00968 | X34: ='SUPUESTOS PRECIOS'!$B$2 -> 0.4 | Y34: =IF(OR($B34="",$J34=""),"",ROUND(($J34+$T34+$U34+$V34)/(1-$W34-$X34),-1)) -> 3430 | Z34: =IF($Y34="","",$Y34-$J34-$T34-$U34-$V34-($Y34*$W34)) -> 1369.2976 | AA34: =IF($Y34="","",$Z34/$Y34) -> 0.39921213 | AB34: TDP-COSTURADO | AC34: SIMPLE
A35: 034 | B35: TDP005 | C35: 🧰 Accesorios y equipamiento | D35: Trapos de piso | E35: bethel | F35: Trapo de piso nido de abeja | H35: 1 unidad | I35: TDP005.jpg | J35: 1300 | K35: 0.3 | L35: =IF(J35="","",J35*(1+K35)) -> 1690 | M35: Activo | O35: Activo | P35: NO | Q35: TDP005 | R35: Trapo de piso nido de abeja. Presentación: 1 unidad. | S35: Trapos de piso. Accesorio resistente y práctico, pensado para facilitar las tareas de limpieza del hogar. | T35: ='SUPUESTOS PRECIOS'!$B$9 -> 0 | U35: ='SUPUESTOS PRECIOS'!$B$5/'SUPUESTOS PRECIOS'!$B$4 -> 1000 | V35: =('SUPUESTOS PRECIOS'!$B$6-'SUPUESTOS PRECIOS'!$B$7)/'SUPUESTOS PRECIOS'!$B$4 -> 377.5 | W35: ='SUPUESTOS PRECIOS'!$B$8 -> 0.00968 | X35: ='SUPUESTOS PRECIOS'!$B$2 -> 0.4 | Y35: =IF(OR($B35="",$J35=""),"",ROUND(($J35+$T35+$U35+$V35)/(1-$W35-$X35),-1)) -> 4540 | Z35: =IF($Y35="","",$Y35-$J35-$T35-$U35-$V35-($Y35*$W35)) -> 1818.5528 | AA35: =IF($Y35="","",$Z35/$Y35) -> 0.40056229
A36: 035 | B36: TDP006 | C36: 🧰 Accesorios y equipamiento | D36: Trapos de piso | E36: bethel | F36: Trapo de piso nido de abeja economico | H36: 1 unidad | I36: TDP006.jpg | K36: 0.3 | L36: =IF(J36="","",J36*(1+K36)) | M36: Activo | O36: Inactivo | P36: NO | Q36: TDP006 | R36: Trapo de piso nido de abeja economico. Presentación: 1 unidad. | S36: Trapos de piso. Accesorio resistente y práctico, pensado para facilitar las tareas de limpieza del hogar. | T36: ='SUPUESTOS PRECIOS'!$B$9 -> 0 | U36: ='SUPUESTOS PRECIOS'!$B$5/'SUPUESTOS PRECIOS'!$B$4 -> 1000 | V36: =('SUPUESTOS PRECIOS'!$B$6-'SUPUESTOS PRECIOS'!$B$7)/'SUPUESTOS PRECIOS'!$B$4 -> 377.5 | W36: ='SUPUESTOS PRECIOS'!$B$8 -> 0.00968 | X36: ='SUPUESTOS PRECIOS'!$B$2 -> 0.4 | Y36: =IF(OR($B36="",$J36=""),"",ROUND(($J36+$T36+$U36+$V36)/(1-$W36-$X36),-1)) | Z36: =IF($Y36="","",$Y36-$J36-$T36-$U36-$V36-($Y36*$W36)) | AA36: =IF($Y36="","",$Z36/$Y36)
A37: 036 | B37: TDP007 | C37: 🧰 Accesorios y equipamiento | D37: Trapos de piso | E37: consorcio | F37: Trapo de piso rayado | H37: 1 unidad | I37: TDP007.jpg | J37: 1100 | K37: 0.3 | L37: =IF(J37="","",J37*(1+K37)) -> 1430 | M37: Activo | O37: Activo | P37: NO | Q37: TDP007 | R37: Trapo de piso rayado. Presentación: 1 unidad. Marca consorcio. | S37: Trapos de piso. Accesorio resistente y práctico, pensado para facilitar las tareas de limpieza del hogar. | T37: ='SUPUESTOS PRECIOS'!$B$9 -> 0 | U37: ='SUPUESTOS PRECIOS'!$B$5/'SUPUESTOS PRECIOS'!$B$4 -> 1000 | V37: =('SUPUESTOS PRECIOS'!$B$6-'SUPUESTOS PRECIOS'!$B$7)/'SUPUESTOS PRECIOS'!$B$4 -> 377.5 | W37: ='SUPUESTOS PRECIOS'!$B$8 -> 0.00968 | X37: ='SUPUESTOS PRECIOS'!$B$2 -> 0.4 | Y37: =IF(OR($B37="",$J37=""),"",ROUND(($J37+$T37+$U37+$V37)/(1-$W37-$X37),-1)) -> 4200 | Z37: =IF($Y37="","",$Y37-$J37-$T37-$U37-$V37-($Y37*$W37)) -> 1681.844 | AA37: =IF($Y37="","",$Z37/$Y37) -> 0.40043905
A38: 037 | B38: TDP008 | C38: 🧰 Accesorios y equipamiento | D38: Trapos de piso | E38: bethel | F38: Trapo de piso rayado | H38: 1 unidad | I38: TDP008.jpg | J38: 1150 | K38: 0.3 | L38: =IF(J38="","",J38*(1+K38)) -> 1495 | M38: Activo | O38: Activo | P38: NO | Q38: TDP008 | R38: Trapo de piso rayado. Presentación: 1 unidad. | S38: Trapos de piso. Accesorio resistente y práctico, pensado para facilitar las tareas de limpieza del hogar. | T38: ='SUPUESTOS PRECIOS'!$B$9 -> 0 | U38: ='SUPUESTOS PRECIOS'!$B$5/'SUPUESTOS PRECIOS'!$B$4 -> 1000 | V38: =('SUPUESTOS PRECIOS'!$B$6-'SUPUESTOS PRECIOS'!$B$7)/'SUPUESTOS PRECIOS'!$B$4 -> 377.5 | W38: ='SUPUESTOS PRECIOS'!$B$8 -> 0.00968 | X38: ='SUPUESTOS PRECIOS'!$B$2 -> 0.4 | Y38: =IF(OR($B38="",$J38=""),"",ROUND(($J38+$T38+$U38+$V38)/(1-$W38-$X38),-1)) -> 4280 | Z38: =IF($Y38="","",$Y38-$J38-$T38-$U38-$V38-($Y38*$W38)) -> 1711.0696 | AA38: =IF($Y38="","",$Z38/$Y38) -> 0.39978262
A39: 038 | B39: EYE001 | C39: 🧰 Accesorios y equipamiento | D39: Escobas y escobillones | E39: bethel | F39: Escoba Anden de 40 cm | H39: 1 unidad | I39: EYE001.jpg | J39: 5100 | K39: 0.3 | L39: =IF(J39="","",J39*(1+K39)) -> 6630 | M39: Activo | O39: Activo | P39: NO | Q39: EYE001 | R39: Escoba Anden de 40 cm. Presentación: 1 unidad. | S39: Escobas y escobillones. Accesorio resistente y práctico, pensado para facilitar las tareas de limpieza del hogar. | T39: ='SUPUESTOS PRECIOS'!$B$9 -> 0 | U39: ='SUPUESTOS PRECIOS'!$B$5/'SUPUESTOS PRECIOS'!$B$4 -> 1000 | V39: =('SUPUESTOS PRECIOS'!$B$6-'SUPUESTOS PRECIOS'!$B$7)/'SUPUESTOS PRECIOS'!$B$4 -> 377.5 | W39: ='SUPUESTOS PRECIOS'!$B$8 -> 0.00968 | X39: ='SUPUESTOS PRECIOS'!$B$2 -> 0.4 | Y39: =IF(OR($B39="",$J39=""),"",ROUND(($J39+$T39+$U39+$V39)/(1-$W39-$X39),-1)) -> 10970 | Z39: =IF($Y39="","",$Y39-$J39-$T39-$U39-$V39-($Y39*$W39)) -> 4386.3104 | AA39: =IF($Y39="","",$Z39/$Y39) -> 0.39984598 | AB39: EYE-ANDEN | AC39: 40 CM
A40: 039 | B40: EYE002 | C40: 🧰 Accesorios y equipamiento | D40: Escobas y escobillones | E40: bethel | F40: Escoba Anden de 60 cm | H40: 1 unidad | I40: EYE002.jpg | J40: 7200 | K40: 0.3 | L40: =IF(J40="","",J40*(1+K40)) -> 9360 | M40: Activo | O40: Activo | P40: NO | Q40: EYE002 | R40: Escoba Anden de 60 cm. Presentación: 1 unidad. | S40: Escobas y escobillones. Accesorio resistente y práctico, pensado para facilitar las tareas de limpieza del hogar. | T40: ='SUPUESTOS PRECIOS'!$B$9 -> 0 | U40: ='SUPUESTOS PRECIOS'!$B$5/'SUPUESTOS PRECIOS'!$B$4 -> 1000 | V40: =('SUPUESTOS PRECIOS'!$B$6-'SUPUESTOS PRECIOS'!$B$7)/'SUPUESTOS PRECIOS'!$B$4 -> 377.5 | W40: ='SUPUESTOS PRECIOS'!$B$8 -> 0.00968 | X40: ='SUPUESTOS PRECIOS'!$B$2 -> 0.4 | Y40: =IF(OR($B40="",$J40=""),"",ROUND(($J40+$T40+$U40+$V40)/(1-$W40-$X40),-1)) -> 14530 | Z40: =IF($Y40="","",$Y40-$J40-$T40-$U40-$V40-($Y40*$W40)) -> 5811.8496 | AA40: =IF($Y40="","",$Z40/$Y40) -> 0.39998965 | AB40: EYE-ANDEN | AC40: 60 CM
...

Sheet CATEGORIAS
A1: 🍽️ Cocina
A2: 🚽 Baño
A3: 🧹 Pisos y superficies
A4: 👕 Ropa y lavado
A5: 🦠 Desinfección y limpieza
A6: 🌸 Aromas y fragancias
A7: 📦 Packs y ofertas
A8: 🧰 Accesorios y equipamiento
A9: 🏊 Piletas
A10: 🚗 Automotor
A11: 🏠 Hogar y varios

Sheet MOVIMIENTOS_STOCK
A1: FECHA | B1: CODIGO | C1: ENTRADA | D1: SALIDA | E1: OBSERVACION

Sheet DASHBOARD
A1: Indicador | B1: Valor
A2: Total Productos | B2: =COUNTA(PRODUCTOS!A2:A201) -> 200

Sheet MARCAS
A1: Bethel
A2: K2
A3: Genérica

Sheet PRESENTACIONES
A1: 500 ml
A2: 1 L
A3: 2 L
A4: 5 L
A5: 10 L
A6: 20 L
A7: 25 kg

Sheet CONTROL_FOTOS
A1: Control de fotos del catálogo
A2: Cómo usarla: revisá cada imagen y completá DECISIÓN con MANTENER o REEMPLAZAR. Para las urgentes, reemplazá la imagen antes de publicar la campaña.
A4: CÓDIGO | B4: PRODUCTO | C4: ARCHIVO ACTUAL | D4: PRIORIDAD | E4: HALLAZGO | F4: FOTO RECOMENDADA | G4: DECISIÓN | H4: NOTAS
A5: CLO001 | B5: Lavandina al 4% | C5: CLO001.jpg | D5: PENDIENTE | E5: Revisar manualmente: producto correcto, imagen nítida, fondo limpio y sin marcas ajenas. | F5: Si se reemplaza: foto real del producto, fondo blanco o neutro, buena luz y encuadre cuadrado. | G5: PENDIENTE
A6: DET001 | B6: Detergente 30% | C6: DET001.jpg | D6: PENDIENTE | E6: Revisar manualmente: producto correcto, imagen nítida, fondo limpio y sin marcas ajenas. | F6: Si se reemplaza: foto real del producto, fondo blanco o neutro, buena luz y encuadre cuadrado. | G6: PENDIENTE
A7: LVA001 | B7: Detergente Magistral listo para usar | C7: LVA001.jpg | D7: PENDIENTE | E7: Revisar manualmente: producto correcto, imagen nítida, fondo limpio y sin marcas ajenas. | F7: Si se reemplaza: foto real del producto, fondo blanco o neutro, buena luz y encuadre cuadrado. | G7: PENDIENTE
A8: LVA002 | B8: Lava-Vajillas Concentrado | C8: LVA002.jpg | D8: PENDIENTE | E8: Revisar manualmente: producto correcto, imagen nítida, fondo limpio y sin marcas ajenas. | F8: Si se reemplaza: foto real del producto, fondo blanco o neutro, buena luz y encuadre cuadrado. | G8: PENDIENTE
A9: SUA001 | B9: Suavizante Blanco por 5 litros | C9: SUA001.jpg | D9: PENDIENTE | E9: Revisar manualmente: producto correcto, imagen nítida, fondo limpio y sin marcas ajenas. | F9: Si se reemplaza: foto real del producto, fondo blanco o neutro, buena luz y encuadre cuadrado. | G9: PENDIENTE
A10: SUA002 | B10: Suavizante listo para usar | C10: SUA002.jpg | D10: PENDIENTE | E10: Revisar manualmente: producto correcto, imagen nítida, fondo limpio y sin marcas ajenas. | F10: Si se reemplaza: foto real del producto, fondo blanco o neutro, buena luz y encuadre cuadrado. | G10: PENDIENTE
A11: JBP001 | B11: Jabon en polvo | C11: JBP001.jpg | D11: PENDIENTE | E11: Revisar manualmente: producto correcto, imagen nítida, fondo limpio y sin marcas ajenas. | F11: Si se reemplaza: foto real del producto, fondo blanco o neutro, buena luz y encuadre cuadrado. | G11: PENDIENTE
A12: PFA001 | B12: Perfume aromatico de base en agua | C12: PFA001.jpg | D12: PENDIENTE | E12: Revisar manualmente: producto correcto, imagen nítida, fondo limpio y sin marcas ajenas. | F12: Si se reemplaza: foto real del producto, fondo blanco o neutro, buena luz y encuadre cuadrado. | G12: PENDIENTE
A13: PFA002 | B13: Perfume aromatico de base en alcohol | C13: PFA002.jpg | D13: PENDIENTE | E13: Revisar manualmente: producto correcto, imagen nítida, fondo limpio y sin marcas ajenas. | F13: Si se reemplaza: foto real del producto, fondo blanco o neutro, buena luz y encuadre cuadrado. | G13: PENDIENTE
A14: DES001 | B14: Desengrasante industrial | C14: DES001.jpg | D14: PENDIENTE | E14: Revisar manualmente: producto correcto, imagen nítida, fondo limpio y sin marcas ajenas. | F14: Si se reemplaza: foto real del producto, fondo blanco o neutro, buena luz y encuadre cuadrado. | G14: PENDIENTE
A15: DES002 | B15: Desengrasante lavamotor | C15: DES002.jpg | D15: PENDIENTE | E15: Revisar manualmente: producto correcto, imagen nítida, fondo limpio y sin marcas ajenas. | F15: Si se reemplaza: foto real del producto, fondo blanco o neutro, buena luz y encuadre cuadrado. | G15: PENDIENTE
A16: DES003 | B16: Desengrasante multi usos | C16: DES003.jpg | D16: PENDIENTE | E16: Revisar manualmente: producto correcto, imagen nítida, fondo limpio y sin marcas ajenas. | F16: Si se reemplaza: foto real del producto, fondo blanco o neutro, buena luz y encuadre cuadrado. | G16: PENDIENTE
... A237: VAR009 | B237: Insecticida liquido Gorrion x 500 cc | C237: VAR009.jpg | D237: PENDIENTE | E237: Revisar manualmente: producto correcto, imagen nítida, fondo limpio y sin marcas ajenas. | F237: Si se reemplaza: foto real del producto, fondo blanco o neutro, buena luz y encuadre cuadrado. | G237: PENDIENTE

Sheet SUPUESTOS PRECIOS
A1: Supuestos para el precio de venta
A2: Margen bruto objetivo | B2: 0.4 | C2: % | D2: Precio calculado para dejar 40% de margen luego de costos y comisión.
A3: Supuesto | B3: Valor | C3: Unidad | D3: Nota
A4: Productos promedio por pedido | B4: 4 | C4: productos | D4: Punto medio de 2 a 6 productos.
A5: Viático de abastecimiento por pedido | B5: 4000 | C5: $ / pedido | D5: Costo de ir a comprar y llevar los productos.
A6: Costo real de entrega por pedido | B6: 4000 | C6: $ / pedido | D6: Costo del reparto al cliente.
A7: Envío cobrado de referencia | B7: 2490 | C7: $ / pedido | D7: Tramo recomendado para compras de $15.000 a $19.999.
A8: Comisión de cobro QR Mercado Pago | B8: 0.00968 | C8: % | D8: 0,8% + IVA. Efectivo o transferencia directa: 0%.
A9: Empaque promedio por producto | B9: 0 | C9: $ / producto | D9: Editable: completalo cuando tengas ese costo.
A11: Fórmula aplicada a PRECIO VENTA AJUSTADO
A12: (Costo del producto + Empaque por producto + Viático prorrateado + Subsidio de envío prorrateado) / (1 - Comisión de cobro - Margen bruto objetivo). La comisión está calculada como porcentaje del precio final. Los importes amarillos son editables; las fórmulas del catálogo se actualizan al abrir Excel.

Sheet TARIFAS ENVÍO
A1: Tarifas de envío a domicilio — referencia operativa
A3: Compra de productos | B3: Envío a cobrar | C3: Costo real de entrega | D3: Subsidio absorbido | E3: Mensaje comercial
A4: $10.000 a $14.999 | B4: 2990 | C4: 4000 | D4: 1010 | E4: Envío a domicilio $2.990
A5: $15.000 a $19.999 | B5: 2490 | C5: 4000 | D5: 1510 | E5: Envío a domicilio $2.490
A6: Desde $20.000 | B6: 1990 | C6: 4000 | D6: 2010 | E6: Envío desde $1.990
A8: Política: se cobra un envío proporcional para atraer pedidos; el negocio absorbe la diferencia entre la tarifa y el costo real. La fórmula de precios usa el subsidio del tramo medio ($2.490 de envío).

Sheet CONTROL PRECIOS
A1: Control de cálculo de precios
A3: Control | B3: Resultado
A4: Productos con costo y precio ajustado | B4: =COUNTIFS(PRODUCTOS!$J$2:$J$1001,">0",PRODUCTOS!$Y$2:$Y$1001,">0") -> 234
A5: Filas con productos cargados | B5: =COUNTIFS(PRODUCTOS!$B$2:$B$1001,"<>",PRODUCTOS!$J$2:$J$1001,">0") -> 234
A6: Margen bruto promedio estimado | B6: =AVERAGEIF(PRODUCTOS!$Y$2:$Y$1001,">0",PRODUCTOS!$AA$2:$AA$1001) -> 0.39997751
A7: Estado | B7: =IF(AND(B4>0,B6>='SUPUESTOS PRECIOS'!$B$2-0.005),"OK","REVISAR") -> OK
